Workbook

Sheet Summary
A1: Switch <-> CBS End-to-End Test Cases
A2: Source: testcase_catalog.py defaults (atm_testcases.json / upi_testcases.json / imps_testcases.json). Expected codes follow ISO mapping in 'NFS Response Code_Banks.pdf'.
A4: Category | B4: ATM | C4: UPI | D4: IMPS | E4: Total
A5: Network Management | B5: =COUNTIFS('ATM Test Cases'!$B$2:$B$129,$A5) -> 6 | C5: =COUNTIFS('UPI Test Cases'!$B$2:$B$117,$A5) -> 6 | D5: =COUNTIFS('IMPS Test Cases'!$B$2:$B$117,$A5) -> 6 | E5: =SUM(B5:D5) -> 18
A6: Positive | B6: =COUNTIFS('ATM Test Cases'!$B$2:$B$129,$A6) -> 6 | C6: =COUNTIFS('UPI Test Cases'!$B$2:$B$117,$A6) -> 5 | D6: =COUNTIFS('IMPS Test Cases'!$B$2:$B$117,$A6) -> 5 | E6: =SUM(B6:D6) -> 16
A7: Negative - Account | B7: =COUNTIFS('ATM Test Cases'!$B$2:$B$129,$A7) -> 10 | C7: =COUNTIFS('UPI Test Cases'!$B$2:$B$117,$A7) -> 13 | D7: =COUNTIFS('IMPS Test Cases'!$B$2:$B$117,$A7) -> 13 | E7: =SUM(B7:D7) -> 36
A8: Negative - Card | B8: =COUNTIFS('ATM Test Cases'!$B$2:$B$129,$A8) -> 7 | C8: =COUNTIFS('UPI Test Cases'!$B$2:$B$117,$A8) -> 0 | D8: =COUNTIFS('IMPS Test Cases'!$B$2:$B$117,$A8) -> 0 | E8: =SUM(B8:D8) -> 7
A9: Boundary | B9: =COUNTIFS('ATM Test Cases'!$B$2:$B$129,$A9) -> 9 | C9: =COUNTIFS('UPI Test Cases'!$B$2:$B$117,$A9) -> 7 | D9: =COUNTIFS('IMPS Test Cases'!$B$2:$B$117,$A9) -> 7 | E9: =SUM(B9:D9) -> 23
A10: Reversal | B10: =COUNTIFS('ATM Test Cases'!$B$2:$B$129,$A10) -> 8 | C10: =COUNTIFS('UPI Test Cases'!$B$2:$B$117,$A10) -> 7 | D10: =COUNTIFS('IMPS Test Cases'!$B$2:$B$117,$A10) -> 7 | E10: =SUM(B10:D10) -> 22
A11: Duplicate | B11: =COUNTIFS('ATM Test Cases'!$B$2:$B$129,$A11) -> 2 | C11: =COUNTIFS('UPI Test Cases'!$B$2:$B$117,$A11) -> 3 | D11: =COUNTIFS('IMPS Test Cases'!$B$2:$B$117,$A11) -> 3 | E11: =SUM(B11:D11) -> 8
A12: Security / Format | B12: =COUNTIFS('ATM Test Cases'!$B$2:$B$129,$A12) -> 14 | C12: =COUNTIFS('UPI Test Cases'!$B$2:$B$117,$A12) -> 11 | D12: =COUNTIFS('IMPS Test Cases'!$B$2:$B$117,$A12) -> 11 | E12: =SUM(B12:D12) -> 36
A13: Timeout / Fault | B13: =COUNTIFS('ATM Test Cases'!$B$2:$B$129,$A13) -> 3 | C13: =COUNTIFS('UPI Test Cases'!$B$2:$B$117,$A13) -> 3 | D13: =COUNTIFS('IMPS Test Cases'!$B$2:$B$117,$A13) -> 3 | E13: =SUM(B13:D13) -> 9
A14: Total test cases | B14: =SUM(B5:B13) -> 65 | C14: =SUM(C5:C13) -> 55 | D14: =SUM(D5:D13) -> 55 | E14: =SUM(E5:E13) -> 175
A16: Execution status | B16: ATM | C16: UPI | D16: IMPS | E16: Total
A17: Pass | B17: =COUNTIFS('ATM Test Cases'!$S$2:$S$129,$A17) -> 0 | C17: =COUNTIFS('UPI Test Cases'!$S$2:$S$117,$A17) -> 0 | D17: =COUNTIFS('IMPS Test Cases'!$S$2:$S$117,$A17) -> 0 | E17: =SUM(B17:D17) -> 0
A18: Fail | B18: =COUNTIFS('ATM Test Cases'!$S$2:$S$129,$A18) -> 0 | C18: =COUNTIFS('UPI Test Cases'!$S$2:$S$117,$A18) -> 0 | D18: =COUNTIFS('IMPS Test Cases'!$S$2:$S$117,$A18) -> 0 | E18: =SUM(B18:D18) -> 0
A19: Blocked | B19: =COUNTIFS('ATM Test Cases'!$S$2:$S$129,$A19) -> 0 | C19: =COUNTIFS('UPI Test Cases'!$S$2:$S$117,$A19) -> 0 | D19: =COUNTIFS('IMPS Test Cases'!$S$2:$S$117,$A19) -> 0 | E19: =SUM(B19:D19) -> 0
A20: Not Run | B20: =COUNTIFS('ATM Test Cases'!$S$2:$S$129,$A20) -> 0 | C20: =COUNTIFS('UPI Test Cases'!$S$2:$S$117,$A20) -> 0 | D20: =COUNTIFS('IMPS Test Cases'!$S$2:$S$117,$A20) -> 0 | E20: =SUM(B20:D20) -> 0
A22: How to use
A23: Blue rows mark the first step of each test case; following rows are its steps (run in order).
A24: Yellow columns (Actual Result, Status, Remarks) are for manual execution notes. Status is a dropdown: Pass / Fail / Blocked / Not Run, and is counted in 'Execution status' above (per step).
A25: Example: Actual Result = 'RC 51, DE 54 avail 100.00' ; Status = Pass ; Remarks = 'Matches NFS 24'.
A26: Automated execution: open the tester app > Testing Suite tab; the same cases run against your CBS and export results to Excel.
A27: UPI / IMPS debit vs credit is tagged in DE 124 (DEBIT / CREDIT) - editable in Channel Settings to match your CBS.
A28: Timeout / Fault cases rely on CBS delay or fault injection (mock CBS: amounts 68.00 late, 91.00 drop, 96.00 RC 96).

Sheet ATM Test Cases
A1: Test Case ID | B1: Category | C1: Priority | D1: Test Case | E1: Description | F1: Profile | G1: Account (DE 102) | H1: Card / PAN (DE 2) | I1: Step | J1: Step Description | K1: Transaction | L1: MTI | M1: Proc Code (DE 3) | N1: Amount | O1: Data / Linkage | P1: Expected Response | Q1: Expected Result | R1: Actual Result | S1: Status | T1: Remarks
A2: ATM_NW_001 | B2: Network Management | C2: P1 | D2: Sign-On (0800 / DE 70 = 001) | E2: Switch signs on to CBS. | F2: standard | G2: 101303130001356 | H2: 6072930130054479 | I2: 1 | J2: 0800 DE70=001 | K2: (linked) | L2: 0800 | O2: Set DE 70=001 | P2: DE 39 = 00; Echo DE 7, 11, 70 | Q2: 0810 with DE 39 = 00; DE 7/11/70 echoed.
A3: ATM_NW_002 | B3: Network Management | C3: P1 | D3: Echo Test (0800 / DE 70 = 301) | E3: Heartbeat between switch and CBS. | F3: standard | G3: 101303130001356 | H3: 6072930130054479 | I3: 1 | J3: 0800 DE70=301 | K3: (linked) | L3: 0800 | O3: Set DE 70=301 | P3: DE 39 = 00; Echo DE 7, 11, 70 | Q3: 0810 with DE 39 = 00.
A4: ATM_NW_003 | B4: Network Management | C4: P2 | D4: Key Exchange (0800 / DE 70 = 101) | E4: Working-key exchange request. | F4: standard | G4: 101303130001356 | H4: 6072930130054479 | I4: 1 | J4: 0800 DE70=101 | K4: (linked) | L4: 0800 | O4: Set DE 70=101 | P4: DE 39 = 00; Echo DE 7, 11, 70 | Q4: 0810 with DE 39 = 00.
A5: ATM_NW_004 | B5: Network Management | C5: P2 | D5: Cut-Over (0800 / DE 70 = 201) | E5: Business-day cut-over notification. | F5: standard | G5: 101303130001356 | H5: 6072930130054479 | I5: 1 | J5: 0800 DE70=201 | K5: (linked) | L5: 0800 | O5: Set DE 70=201 | P5: DE 39 = 00; Echo DE 7, 11, 70 | Q5: 0810 with DE 39 = 00.
A6: ATM_NW_005 | B6: Network Management | C6: P2 | D6: Sign-Off (0800 / DE 70 = 002) | E6: Switch signs off from CBS. | F6: standard | G6: 101303130001356 | H6: 6072930130054479 | I6: 1 | J6: 0800 DE70=002 | K6: (linked) | L6: 0800 | O6: Set DE 70=002 | P6: DE 39 = 00; Echo DE 7, 11, 70 | Q6: 0810 with DE 39 = 00.
A7: ATM_NW_006 | B7: Network Management | C7: P3 | D7: Invalid Network Code (DE 70 = 555) | E7: Unsupported network management code. | F7: standard | G7: 101303130001356 | H7: 6072930130054479 | I7: 1 | J7: 0800 DE70=555 | K7: (linked) | L7: 0800 | O7: Set DE 70=555 | P7: DE 39 = 12 / 30; Echo DE 7, 11, 70 | Q7: 0810 declined with 12 / 30.
A8: ATM_POS_001 | B8: Positive | C8: P1 | D8: Cash Withdrawal - Approved with Balance Debit Verification | E8: Withdraw 500.00 and verify the account is debited by exactly 500.00 in DE 54. | F8: standard | G8: 101303130001356 | H8: 6072930130054479 | I8: 1 | J8: Opening balance | K8: balance_inquiry | L8: 0200 | M8: 311000 | P8: DE 39 = 00; DE present: 54 | Q8: 0210 RC 00; available balance reduced by 500.00; DE 2/3/4/11/37/102 echoed.
I9: 2 | J9: Cash withdrawal | K9: issuer_cash_withdrawal | L9: 0200 | M9: 011000 | N9: 500.00 | P9: DE 39 = 00; Available balance -500.00 vs step 1
I10: 3 | J10: Cleanup reversal | K10: (linked) | L10: 0420 | O10: Reversal 0420 of step 2 (DE 39 reason 68) | P10: DE 39 = 00; Available balance 0.00 vs step 1
A11: ATM_POS_002 | B11: Positive | C11: P1 | D11: Balance Enquiry - Approved with DE 54 | E11: Balance enquiry returns ledger and available balances. | F11: standard | G11: 101303130001356 | H11: 6072930130054479 | I11: 1 | J11: Balance enquiry | K11: balance_inquiry | L11: 0200 | M11: 311000 | N11: 0.00 | P11: DE 39 = 00; DE present: 54; DE absent: 48; Format check DE 54 | Q11: 0210 RC 00; DE 54 well-formed (ledger 01 + available 02).
A12: ATM_POS_003 | B12: Positive | C12: P1 | D12: Mini Statement - Approved with DE 63 | E12: Mini statement returns statement lines in DE 63. | F12: standard | G12: 101303130001356 | H12: 6072930130054479 | I12: 1 | J12: Mini statement | K12: mini_statement | L12: 0200 | M12: 380000 | N12: 0.00 | P12: DE 39 = 00; DE present: 54, 63; DE absent: 48 | Q12: 0210 RC 00; DE 63 statement + DE 54 balances.
A13: ATM_POS_004 | B13: Positive | C13: P1 | D13: POS Purchase - Approved with Balance Debit | E13: Card-present POS purchase debits the account. | F13: standard | G13: 101303130001356 | H13: 6072930130054479 | I13: 1 | J13: Opening balance | K13: balance_inquiry | L13: 0200 | M13: 311000 | P13: DE 39 = 00; DE present: 54 | Q13: 0210 RC 00; DE 48 retained; balance reduced by 2500.00.
I14: 2 | J14: POS purchase | K14: pos_purchase | L14: 0200 | M14: 000000 | N14: 2500.00 | O14: Set DE 18=5411, DE 41=EP025109 | P14: DE 39 = 00; DE present: 48, 54; Available balance -2500.00 vs step 1
I15: 3 | J15: Cleanup POS reversal | K15: (linked) | L15: 0420 | O15: Reversal 0420 of step 2 (DE 39 reason 68) | P15: DE 39 = 00; Available balance 0.00 vs step 1
A16: ATM_POS_005 | B16: Positive | C16: P1 | D16: E-Commerce Purchase - Approved with Balance Debit | E16: Card-not-present purchase (DE 22 = 810, DE 25 = 59). | F16: standard | G16: 101303130001356 | H16: 6072930130054479 | I16: 1 | J16: Opening balance | K16: balance_inquiry | L16: 0200 | M16: 311000 | P16: DE 39 = 00; DE present: 54 | Q16: 0210 RC 00; balance reduced by 1500.00; reversal 00 / 09 (in progress).
I17: 2 | J17: E-com purchase | K17: ecom_purchase | L17: 0200 | M17: 000000 | N17: 1500.00 | O17: Set DE 18=5814, DE 41=70016942 | P17: DE 39 = 00; DE present: 14, 54; Available balance -1500.00 vs step 1
I18: 3 | J18: Cleanup e-com reversal | K18: (linked) | L18: 0420 | O18: Reversal 0420 of step 2 (DE 39 reason 68) | P18: DE 39 = 00 / 09; Available balance 0.00 vs step 1
A19: ATM_POS_006 | B19: Positive | C19: P2 | D19: Cash Withdrawal with Fee in DE 46 (Over Quota) | E19: Interchange fee carried in DE 46 is passed through to CBS. | F19: standard | G19: 101303130001356 | H19: 6072930130054479 | I19: 1 | J19: Opening balance | K19: balance_inquiry | L19: 0200 | M19: 311000 | P19: DE 39 = 00; DE present: 54 | Q19: 0210 RC 00; DE 46 echoed unchanged.
I20: 2 | J20: Cash withdrawal with DE 46 | K20: issuer_cash_withdrawal | L20: 0200 | M20: 011000 | N20: 500.00 | O20: Set DE 46=ICH356D000000002100 | P20: DE 39 = 00; DE present: 46, 54; Available balance -500.00 vs step 1
I21: 3 | J21: Cleanup reversal | K21: (linked) | L21: 0420 | O21: Reversal 0420 of step 2 (DE 39 reason 68) | P21: DE 39 = 00; Available balance 0.00 vs step 1
A22: ATM_NA_001 | B22: Negative - Account | C22: P1 | D22: Closed Account - Cash Withdrawal | F22: closed | G22: 0020001010011800 | H22: 6072930130011800 | I22: 1 | J22: Cash withdrawal | K22: issuer_cash_withdrawal | L22: 0200 | M22: 011000 | N22: 500.00 | P22: DE 39 = 52 / 53 / 39 / 42 / 14 | Q22: Declined with invalid-account code (52/53/39/42/14).
A23: ATM_NA_002 | B23: Negative - Account | C23: P1 | D23: Closed Account - Balance Enquiry | F23: closed | G23: 0020001010011800 | H23: 6072930130011800 | I23: 1 | J23: Balance enquiry | K23: balance_inquiry | L23: 0200 | M23: 311000 | N23: 0.00 | P23: DE 39 = 52 / 53 / 39 / 42 / 14 | Q23: Declined with invalid-account code.
A24: ATM_NA_003 | B24: Negative - Account | C24: P1 | D24: Closed Account - Mini Statement | F24: closed | G24: 0020001010011800 | H24: 6072930130011800 | I24: 1 | J24: Mini statement | K24: mini_statement | L24: 0200 | M24: 380000 | N24: 0.00 | P24: DE 39 = 52 / 53 / 39 / 42 / 14; DE absent: 63 | Q24: Declined; no statement lines (DE 63) returned.
A25: ATM_NA_004 | B25: Negative - Account | C25: P1 | D25: Closed Account - POS Purchase | F25: closed | G25: 0020001010011800 | H25: 6072930130011800 | I25: 1 | J25: POS purchase | K25: pos_purchase | L25: 0200 | M25: 000000 | N25: 2500.00 | O25: Set DE 18=5411, DE 41=EP025109 | P25: DE 39 = 52 / 53 / 39 / 42 / 14 | Q25: Declined with invalid-account code.
A26: ATM_NA_005 | B26: Negative - Account | C26: P1 | D26: Total Freeze Account - Cash Withdrawal | F26: total_freeze | G26: 0020001010011663 | H26: 6072930130011663 | I26: 1 | J26: Cash withdrawal | K26: issuer_cash_withdrawal | L26: 0200 | M26: 011000 | N26: 500.00 | P26: DE 39 = 62 / 57 / 05 | Q26: Declined 62 / 57 / 05.
A27: ATM_NA_006 | B27: Negative - Account | C27: P1 | D27: Debit Freeze Account - Cash Withdrawal | F27: debit_freeze | G27: 0020001010011664 | H27: 6072930130011664 | I27: 1 | J27: Cash withdrawal | K27: issuer_cash_withdrawal | L27: 0200 | M27: 011000 | N27: 500.00 | P27: DE 39 = 62 / 57 / 05 | Q27: Declined 62 / 57 / 05.
A28: ATM_NA_007 | B28: Negative - Account | C28: P1 | D28: Dormant Account - Cash Withdrawal | F28: dormant | G28: 0020001010011700 | H28: 6072930130011700 | I28: 1 | J28: Cash withdrawal | K28: issuer_cash_withdrawal | L28: 0200 | M28: 011000 | N28: 500.00 | P28: DE 39 = 57 / 62 / 05 | Q28: Declined 57 / 62 / 05.
A29: ATM_NA_008 | B29: Negative - Account | C29: P1 | D29: Insufficient Funds - No Debit Posted | F29: low_funds | G29: 0020001010010999 | H29: 6072930130010999 | I29: 1 | J29: Opening balance | K29: balance_inquiry | L29: 0200 | M29: 311000 | P29: DE 39 = 00; DE present: 54 | Q29: Declined 51; balance unchanged.
I30: 2 | J30: Cash withdrawal | K30: issuer_cash_withdrawal | L30: 0200 | M30: 011000 | N30: 500.00 | P30: DE 39 = 51
I31: 3 | J31: Closing balance | K31: balance_inquiry | L31: 0200 | M31: 311000 | P31: DE 39 = 00; DE present: 54; Available balance 0.00 vs step 1
A32: ATM_NA_009 | B32: Negative - Account | C32: P1 | D32: Minimum Balance Breach | F32: min_balance | G32: 0020001010010463 | H32: 6072930130010463 | I32: 1 | J32: Opening balance | K32: balance_inquiry | L32: 0200 | M32: 311000 | P32: DE 39 = 00; DE present: 54 | Q32: Declined 51 (would breach min balance 1000); balance unchanged.
I33: 2 | J33: Cash withdrawal | K33: issuer_cash_withdrawal | L33: 0200 | M33: 011000 | N33: 600.00 | P33: DE 39 = 51
I34: 3 | J34: Closing balance | K34: balance_inquiry | L34: 0200 | M34: 311000 | P34: DE 39 = 00; DE present: 54; Available balance 0.00 vs step 1
A35: ATM_NA_010 | B35: Negative - Account | C35: P1 | D35: Account Not Found in CBS | F35: not_found | G35: 0020009999999999 | H35: 6072930130000000 | I35: 1 | J35: Cash withdrawal | K35: issuer_cash_withdrawal | L35: 0200 | M35: 011000 | N35: 500.00 | P35: DE 39 = 52 / 53 / 39 / 42 / 14 | Q35: Declined with invalid-account code.
A36: ATM_NC_001 | B36: Negative - Card | C36: P1 | D36: Invalid / Unallocated BIN | F36: invalid_bin | G36: 101303130001356 | H36: 9999990000000001 | I36: 1 | J36: Cash withdrawal | K36: issuer_cash_withdrawal | L36: 0200 | M36: 011000 | N36: 500.00 | P36: DE 39 = 15 / 92 / 14 | Q36: Declined 15 / 92 / 14.
A37: ATM_NC_002 | B37: Negative - Card | C37: P1 | D37: Unknown Card Number (valid BIN) | F37: unknown_card | G37: 101303130001356 | H37: 6072930199999999 | I37: 1 | J37: Cash withdrawal | K37: issuer_cash_withdrawal | L37: 0200 | M37: 011000 | N37: 500.00 | P37: DE 39 = 14 | Q37: Declined 14 (no such card).
A38: ATM_NC_003 | B38: Negative - Card | C38: P1 | D38: Expired Card - Cash Withdrawal | F38: expired_card | G38: 101303130001356 | H38: 6072930130099990 | I38: 1 | J38: Cash withdrawal | K38: issuer_cash_withdrawal | L38: 0200 | M38: 011000 | N38: 500.00 | P38: DE 39 = 54 / 33 | Q38: Declined 54 / 33.
A39: ATM_NC_004 | B39: Negative - Card | C39: P1 | D39: Lost Card | F39: lost_card | G39: 101303130001356 | H39: 6072930130041000 | I39: 1 | J39: Cash withdrawal | K39: issuer_cash_withdrawal | L39: 0200 | M39: 011000 | N39: 500.00 | P39: DE 39 = 41 | Q39: Declined 41.
A40: ATM_NC_005 | B40: Negative - Card | C40: P1 | D40: Stolen Card | F40: stolen_card | G40: 101303130001356 | H40: 6072930130043000 | I40: 1 | J40: Cash withdrawal | K40: issuer_cash_withdrawal | L40: 0200 | M40: 011000 | N40: 500.00 | P40: DE 39 = 43 | Q40: Declined 43.
...

Sheet UPI Test Cases
A1: Test Case ID | B1: Category | C1: Priority | D1: Test Case | E1: Description | F1: Profile | G1: Account (DE 102) | H1: Card / PAN (DE 2) | I1: Step | J1: Step Description | K1: Transaction | L1: MTI | M1: Proc Code (DE 3) | N1: Amount | O1: Data / Linkage | P1: Expected Response | Q1: Expected Result | R1: Actual Result | S1: Status | T1: Remarks
A2: UPI_NW_001 | B2: Network Management | C2: P1 | D2: Sign-On (0800 / DE 70 = 001) | E2: Switch signs on to CBS. | F2: standard | G2: 0020001010000069 | H2: 8180073930053234 | I2: 1 | J2: 0800 DE70=001 | K2: (linked) | L2: 0800 | O2: Set DE 70=001 | P2: DE 39 = 00; Echo DE 7, 11, 70 | Q2: 0810 with DE 39 = 00; DE 7/11/70 echoed.
A3: UPI_NW_002 | B3: Network Management | C3: P1 | D3: Echo Test (0800 / DE 70 = 301) | E3: Heartbeat between switch and CBS. | F3: standard | G3: 0020001010000069 | H3: 8180073930053234 | I3: 1 | J3: 0800 DE70=301 | K3: (linked) | L3: 0800 | O3: Set DE 70=301 | P3: DE 39 = 00; Echo DE 7, 11, 70 | Q3: 0810 with DE 39 = 00.
A4: UPI_NW_003 | B4: Network Management | C4: P2 | D4: Key Exchange (0800 / DE 70 = 101) | E4: Working-key exchange request. | F4: standard | G4: 0020001010000069 | H4: 8180073930053234 | I4: 1 | J4: 0800 DE70=101 | K4: (linked) | L4: 0800 | O4: Set DE 70=101 | P4: DE 39 = 00; Echo DE 7, 11, 70 | Q4: 0810 with DE 39 = 00.
A5: UPI_NW_004 | B5: Network Management | C5: P2 | D5: Cut-Over (0800 / DE 70 = 201) | E5: Business-day cut-over notification. | F5: standard | G5: 0020001010000069 | H5: 8180073930053234 | I5: 1 | J5: 0800 DE70=201 | K5: (linked) | L5: 0800 | O5: Set DE 70=201 | P5: DE 39 = 00; Echo DE 7, 11, 70 | Q5: 0810 with DE 39 = 00.
A6: UPI_NW_005 | B6: Network Management | C6: P2 | D6: Sign-Off (0800 / DE 70 = 002) | E6: Switch signs off from CBS. | F6: standard | G6: 0020001010000069 | H6: 8180073930053234 | I6: 1 | J6: 0800 DE70=002 | K6: (linked) | L6: 0800 | O6: Set DE 70=002 | P6: DE 39 = 00; Echo DE 7, 11, 70 | Q6: 0810 with DE 39 = 00.
A7: UPI_NW_006 | B7: Network Management | C7: P3 | D7: Invalid Network Code (DE 70 = 555) | E7: Unsupported network management code. | F7: standard | G7: 0020001010000069 | H7: 8180073930053234 | I7: 1 | J7: 0800 DE70=555 | K7: (linked) | L7: 0800 | O7: Set DE 70=555 | P7: DE 39 = 12 / 30; Echo DE 7, 11, 70 | Q7: 0810 declined with 12 / 30.
A8: UPI_POS_001 | B8: Positive | C8: P1 | D8: UPI List Account / Account Verification | F8: standard | G8: 0020001010000069 | H8: 8180073930053234 | I8: 1 | J8: List account | K8: upi_list_account | L8: 0200 | M8: 410000 | P8: DE 39 = 00; DE present: 102 | Q8: 0210 RC 00; DE 102 echoed.
A9: UPI_POS_002 | B9: Positive | C9: P1 | D9: UPI Balance Enquiry with DE 54 | F9: standard | G9: 0020001010000069 | H9: 8180073930053234 | I9: 1 | J9: Balance enquiry | K9: upi_balance_enquiry | L9: 0200 | M9: 310000 | N9: 0.00 | P9: DE 39 = 00; DE present: 54; Format check DE 54 | Q9: 0210 RC 00; DE 54 well-formed.
A10: UPI_POS_003 | B10: Positive | C10: P1 | D10: UPI Outward Pay (Debit) - Balance Debited | F10: standard | G10: 0020001010000069 | H10: 8180073930053234 | I10: 1 | J10: Opening balance | K10: upi_balance_enquiry | L10: 0200 | M10: 310000 | N10: 0.00 | P10: DE 39 = 00; DE present: 54 | Q10: 0210 RC 00; balance reduced by 1000.00.
I11: 2 | J11: Outward debit | K11: upi_outward | L11: 0200 | M11: 000000 | N11: 1000.00 | O11: Debit (direction tag) | P11: DE 39 = 00; Available balance -1000.00 vs step 1
I12: 3 | J12: Cleanup reversal | K12: (linked) | L12: 0420 | O12: Reversal 0420 of step 2 (DE 39 reason 68) | P12: DE 39 = 00; Available balance 0.00 vs step 1
A13: UPI_POS_004 | B13: Positive | C13: P1 | D13: UPI Inward Pay (Credit) - Balance Credited | F13: standard | G13: 0020001010000069 | H13: 8180073930053234 | I13: 1 | J13: Opening balance | K13: upi_balance_enquiry | L13: 0200 | M13: 310000 | N13: 0.00 | P13: DE 39 = 00; DE present: 54 | Q13: 0210 RC 00; balance increased by 1000.00.
I14: 2 | J14: Inward credit | K14: upi_inward | L14: 0200 | M14: 000000 | N14: 1000.00 | O14: Credit (direction tag) | P14: DE 39 = 00; Available balance 1000.00 vs step 1
I15: 3 | J15: Cleanup reversal (credit) | K15: (linked) | L15: 0420 | O15: Reversal 0420 of step 2 (DE 39 reason 68) | P15: DE 39 = 00; Available balance 0.00 vs step 1
A16: UPI_POS_005 | B16: Positive | C16: P2 | D16: UPI Outward then Inward (Round Trip) | F16: standard | G16: 0020001010000069 | H16: 8180073930053234 | I16: 1 | J16: Opening balance | K16: upi_balance_enquiry | L16: 0200 | M16: 310000 | N16: 0.00 | P16: DE 39 = 00; DE present: 54 | Q16: Both approved; net balance unchanged.
I17: 2 | J17: Outward debit | K17: upi_outward | L17: 0200 | M17: 000000 | N17: 250.00 | O17: Debit (direction tag) | P17: DE 39 = 00
I18: 3 | J18: Inward credit | K18: upi_inward | L18: 0200 | M18: 000000 | N18: 250.00 | O18: Credit (direction tag) | P18: DE 39 = 00; Available balance 0.00 vs step 1
A19: UPI_NA_001 | B19: Negative - Account | C19: P1 | D19: Closed Account - List Account | F19: closed | G19: 0020001010011800 | H19: 8180073930053234 | I19: 1 | J19: List account | K19: upi_list_account | L19: 0200 | M19: 410000 | P19: DE 39 = 52 / 53 / 39 / 42 / 14 | Q19: Declined with invalid-account code.
A20: UPI_NA_002 | B20: Negative - Account | C20: P1 | D20: Closed Account - Outward Debit | F20: closed | G20: 0020001010011800 | H20: 8180073930053234 | I20: 1 | J20: Outward debit | K20: upi_outward | L20: 0200 | M20: 000000 | N20: 1000.00 | O20: Debit (direction tag) | P20: DE 39 = 52 / 53 / 39 / 42 / 14 | Q20: Declined with invalid-account code.
A21: UPI_NA_003 | B21: Negative - Account | C21: P1 | D21: Closed Account - Inward Credit | F21: closed | G21: 0020001010011800 | H21: 8180073930053234 | I21: 1 | J21: Inward credit | K21: upi_inward | L21: 0200 | M21: 000000 | N21: 1000.00 | O21: Credit (direction tag) | P21: DE 39 = 52 / 53 / 39 / 42 / 14 | Q21: Credit to closed account rejected.
A22: UPI_NA_004 | B22: Negative - Account | C22: P1 | D22: Account Not Found - Outward Debit | F22: not_found | G22: 0020009999999999 | H22: 8180073930053234 | I22: 1 | J22: Outward debit | K22: upi_outward | L22: 0200 | M22: 000000 | N22: 1000.00 | O22: Debit (direction tag) | P22: DE 39 = 52 / 53 / 39 / 42 / 14 | Q22: Declined with invalid-account code.
A23: UPI_NA_005 | B23: Negative - Account | C23: P1 | D23: Beneficiary Not Found - Inward Credit | F23: not_found | G23: 0020009999999999 | H23: 8180073930053234 | I23: 1 | J23: Inward credit | K23: upi_inward | L23: 0200 | M23: 000000 | N23: 1000.00 | O23: Credit (direction tag) | P23: DE 39 = 52 / 53 / 39 / 42 / 14 | Q23: Declined with invalid-account code.
A24: UPI_NA_006 | B24: Negative - Account | C24: P1 | D24: Total Freeze - Outward Debit | F24: total_freeze | G24: 0020001010011663 | H24: 8180073930053234 | I24: 1 | J24: Outward debit | K24: upi_outward | L24: 0200 | M24: 000000 | N24: 1000.00 | O24: Debit (direction tag) | P24: DE 39 = 62 / 57 / 05 | Q24: Declined 62 / 57 / 05.
A25: UPI_NA_007 | B25: Negative - Account | C25: P1 | D25: Total Freeze - Inward Credit | F25: total_freeze | G25: 0020001010011663 | H25: 8180073930053234 | I25: 1 | J25: Inward credit | K25: upi_inward | L25: 0200 | M25: 000000 | N25: 1000.00 | O25: Credit (direction tag) | P25: DE 39 = 62 / 57 / 05 | Q25: Declined 62 / 57 / 05.
A26: UPI_NA_008 | B26: Negative - Account | C26: P1 | D26: Debit Freeze - Outward Debit Blocked | F26: debit_freeze | G26: 0020001010011664 | H26: 8180073930053234 | I26: 1 | J26: Outward debit | K26: upi_outward | L26: 0200 | M26: 000000 | N26: 1000.00 | O26: Debit (direction tag) | P26: DE 39 = 62 / 57 / 05 | Q26: Declined 62 / 57 / 05.
A27: UPI_NA_009 | B27: Negative - Account | C27: P1 | D27: Debit Freeze - Inward Credit Allowed | F27: debit_freeze | G27: 0020001010011664 | H27: 8180073930053234 | I27: 1 | J27: Inward credit | K27: upi_inward | L27: 0200 | M27: 000000 | N27: 100.00 | O27: Credit (direction tag) | P27: DE 39 = 00 | Q27: Credit approved 00.
I28: 2 | J28: Cleanup reversal | K28: (linked) | L28: 0420 | O28: Reversal 0420 of step 1 (DE 39 reason 68) | P28: DE 39 = 00
A29: UPI_NA_010 | B29: Negative - Account | C29: P1 | D29: Credit Freeze - Inward Credit Blocked | F29: credit_freeze | G29: 0020001010011665 | H29: 8180073930053234 | I29: 1 | J29: Inward credit | K29: upi_inward | L29: 0200 | M29: 000000 | N29: 1000.00 | O29: Credit (direction tag) | P29: DE 39 = 62 / 57 / 05 | Q29: Declined 62 / 57 / 05.
A30: UPI_NA_011 | B30: Negative - Account | C30: P1 | D30: Credit Freeze - Outward Debit Allowed | F30: credit_freeze | G30: 0020001010011665 | H30: 8180073930053234 | I30: 1 | J30: Outward debit | K30: upi_outward | L30: 0200 | M30: 000000 | N30: 100.00 | O30: Debit (direction tag) | P30: DE 39 = 00 | Q30: Debit approved 00.
I31: 2 | J31: Cleanup reversal | K31: (linked) | L31: 0420 | O31: Reversal 0420 of step 1 (DE 39 reason 68) | P31: DE 39 = 00
A32: UPI_NA_012 | B32: Negative - Account | C32: P1 | D32: Dormant Account - Outward Debit | F32: dormant | G32: 0020001010011700 | H32: 8180073930053234 | I32: 1 | J32: Outward debit | K32: upi_outward | L32: 0200 | M32: 000000 | N32: 1000.00 | O32: Debit (direction tag) | P32: DE 39 = 57 / 62 / 05 | Q32: Declined 57 / 62 / 05.
A33: UPI_NA_013 | B33: Negative - Account | C33: P1 | D33: Insufficient Funds - No Debit Posted | F33: low_funds | G33: 0020001010010999 | H33: 8180073930053234 | I33: 1 | J33: Opening balance | K33: upi_balance_enquiry | L33: 0200 | M33: 310000 | N33: 0.00 | P33: DE 39 = 00; DE present: 54 | Q33: Declined 51; balance unchanged.
I34: 2 | J34: Outward debit | K34: upi_outward | L34: 0200 | M34: 000000 | N34: 500.00 | O34: Debit (direction tag) | P34: DE 39 = 51
I35: 3 | J35: Closing balance | K35: upi_balance_enquiry | L35: 0200 | M35: 310000 | N35: 0.00 | P35: DE 39 = 00; DE present: 54; Available balance 0.00 vs step 1
A36: UPI_BD_001 | B36: Boundary | C36: P1 | D36: Zero Amount Debit | F36: standard | G36: 0020001010000069 | H36: 8180073930053234 | I36: 1 | J36: Outward debit | K36: upi_outward | L36: 0200 | M36: 000000 | N36: 0.00 | O36: Debit (direction tag) | P36: DE 39 = 13 | Q36: Declined 13.
A37: UPI_BD_002 | B37: Boundary | C37: P1 | D37: Debit = Per-Transaction Limit (100000.00) | F37: standard | G37: 0020001010000069 | H37: 8180073930053234 | I37: 1 | J37: Outward debit | K37: upi_outward | L37: 0200 | M37: 000000 | N37: 100000.00 | O37: Debit (direction tag) | P37: DE 39 = 00 | Q37: Approved 00 at the exact limit.
I38: 2 | J38: Cleanup reversal | K38: (linked) | L38: 0420 | O38: Reversal 0420 of step 1 (DE 39 reason 68) | P38: DE 39 = 00
A39: UPI_BD_003 | B39: Boundary | C39: P1 | D39: Debit = Limit + 0.01 (100000.01) | F39: standard | G39: 0020001010000069 | H39: 8180073930053234 | I39: 1 | J39: Outward debit | K39: upi_outward | L39: 0200 | M39: 000000 | N39: 100000.01 | O39: Debit (direction tag) | P39: DE 39 = 61 | Q39: Declined 61.
A40: UPI_BD_004 | B40: Boundary | C40: P2 | D40: Minimum Debit (1.00) | F40: standard | G40: 0020001010000069 | H40: 8180073930053234 | I40: 1 | J40: Outward debit | K40: upi_outward | L40: 0200 | M40: 000000 | N40: 1.00 | O40: Debit (direction tag) | P40: DE 39 = 00 | Q40: Approved 00.
...

Sheet IMPS Test Cases
A1: Test Case ID | B1: Category | C1: Priority | D1: Test Case | E1: Description | F1: Profile | G1: Account (DE 102) | H1: Card / PAN (DE 2) | I1: Step | J1: Step Description | K1: Transaction | L1: MTI | M1: Proc Code (DE 3) | N1: Amount | O1: Data / Linkage | P1: Expected Response | Q1: Expected Result | R1: Actual Result | S1: Status | T1: Remarks
A2: IMPS_NW_001 | B2: Network Management | C2: P1 | D2: Sign-On (0800 / DE 70 = 001) | E2: Switch signs on to CBS. | F2: standard | G2: 0020001010000069 | H2: 8180073930053234 | I2: 1 | J2: 0800 DE70=001 | K2: (linked) | L2: 0800 | O2: Set DE 70=001 | P2: DE 39 = 00; Echo DE 7, 11, 70 | Q2: 0810 with DE 39 = 00; DE 7/11/70 echoed.
A3: IMPS_NW_002 | B3: Network Management | C3: P1 | D3: Echo Test (0800 / DE 70 = 301) | E3: Heartbeat between switch and CBS. | F3: standard | G3: 0020001010000069 | H3: 8180073930053234 | I3: 1 | J3: 0800 DE70=301 | K3: (linked) | L3: 0800 | O3: Set DE 70=301 | P3: DE 39 = 00; Echo DE 7, 11, 70 | Q3: 0810 with DE 39 = 00.
A4: IMPS_NW_003 | B4: Network Management | C4: P2 | D4: Key Exchange (0800 / DE 70 = 101) | E4: Working-key exchange request. | F4: standard | G4: 0020001010000069 | H4: 8180073930053234 | I4: 1 | J4: 0800 DE70=101 | K4: (linked) | L4: 0800 | O4: Set DE 70=101 | P4: DE 39 = 00; Echo DE 7, 11, 70 | Q4: 0810 with DE 39 = 00.
A5: IMPS_NW_004 | B5: Network Management | C5: P2 | D5: Cut-Over (0800 / DE 70 = 201) | E5: Business-day cut-over notification. | F5: standard | G5: 0020001010000069 | H5: 8180073930053234 | I5: 1 | J5: 0800 DE70=201 | K5: (linked) | L5: 0800 | O5: Set DE 70=201 | P5: DE 39 = 00; Echo DE 7, 11, 70 | Q5: 0810 with DE 39 = 00.
A6: IMPS_NW_005 | B6: Network Management | C6: P2 | D6: Sign-Off (0800 / DE 70 = 002) | E6: Switch signs off from CBS. | F6: standard | G6: 0020001010000069 | H6: 8180073930053234 | I6: 1 | J6: 0800 DE70=002 | K6: (linked) | L6: 0800 | O6: Set DE 70=002 | P6: DE 39 = 00; Echo DE 7, 11, 70 | Q6: 0810 with DE 39 = 00.
A7: IMPS_NW_006 | B7: Network Management | C7: P3 | D7: Invalid Network Code (DE 70 = 555) | E7: Unsupported network management code. | F7: standard | G7: 0020001010000069 | H7: 8180073930053234 | I7: 1 | J7: 0800 DE70=555 | K7: (linked) | L7: 0800 | O7: Set DE 70=555 | P7: DE 39 = 12 / 30; Echo DE 7, 11, 70 | Q7: 0810 declined with 12 / 30.
A8: IMPS_POS_001 | B8: Positive | C8: P1 | D8: IMPS List Account / Account Verification | F8: standard | G8: 0020001010000069 | H8: 8180073930053234 | I8: 1 | J8: List account | K8: imps_list_account | L8: 0200 | M8: 410000 | P8: DE 39 = 00; DE present: 102 | Q8: 0210 RC 00; DE 102 echoed.
A9: IMPS_POS_002 | B9: Positive | C9: P1 | D9: IMPS Balance Enquiry with DE 54 | F9: standard | G9: 0020001010000069 | H9: 8180073930053234 | I9: 1 | J9: Balance enquiry | K9: imps_balance_enquiry | L9: 0200 | M9: 310000 | N9: 0.00 | P9: DE 39 = 00; DE present: 54; Format check DE 54 | Q9: 0210 RC 00; DE 54 well-formed.
A10: IMPS_POS_003 | B10: Positive | C10: P1 | D10: IMPS Outward Pay (Debit) - Balance Debited | F10: standard | G10: 0020001010000069 | H10: 8180073930053234 | I10: 1 | J10: Opening balance | K10: imps_balance_enquiry | L10: 0200 | M10: 310000 | N10: 0.00 | P10: DE 39 = 00; DE present: 54 | Q10: 0210 RC 00; balance reduced by 1000.00.
I11: 2 | J11: Outward debit | K11: imps_outward | L11: 0200 | M11: 000000 | N11: 1000.00 | O11: Debit (direction tag) | P11: DE 39 = 00; Available balance -1000.00 vs step 1
I12: 3 | J12: Cleanup reversal | K12: (linked) | L12: 0420 | O12: Reversal 0420 of step 2 (DE 39 reason 68) | P12: DE 39 = 00; Available balance 0.00 vs step 1
A13: IMPS_POS_004 | B13: Positive | C13: P1 | D13: IMPS Inward Pay (Credit) - Balance Credited | F13: standard | G13: 0020001010000069 | H13: 8180073930053234 | I13: 1 | J13: Opening balance | K13: imps_balance_enquiry | L13: 0200 | M13: 310000 | N13: 0.00 | P13: DE 39 = 00; DE present: 54 | Q13: 0210 RC 00; balance increased by 1000.00.
I14: 2 | J14: Inward credit | K14: imps_inward | L14: 0200 | M14: 000000 | N14: 1000.00 | O14: Credit (direction tag) | P14: DE 39 = 00; Available balance 1000.00 vs step 1
I15: 3 | J15: Cleanup reversal (credit) | K15: (linked) | L15: 0420 | O15: Reversal 0420 of step 2 (DE 39 reason 68) | P15: DE 39 = 00; Available balance 0.00 vs step 1
A16: IMPS_POS_005 | B16: Positive | C16: P2 | D16: IMPS Outward then Inward (Round Trip) | F16: standard | G16: 0020001010000069 | H16: 8180073930053234 | I16: 1 | J16: Opening balance | K16: imps_balance_enquiry | L16: 0200 | M16: 310000 | N16: 0.00 | P16: DE 39 = 00; DE present: 54 | Q16: Both approved; net balance unchanged.
I17: 2 | J17: Outward debit | K17: imps_outward | L17: 0200 | M17: 000000 | N17: 250.00 | O17: Debit (direction tag) | P17: DE 39 = 00
I18: 3 | J18: Inward credit | K18: imps_inward | L18: 0200 | M18: 000000 | N18: 250.00 | O18: Credit (direction tag) | P18: DE 39 = 00; Available balance 0.00 vs step 1
A19: IMPS_NA_001 | B19: Negative - Account | C19: P1 | D19: Closed Account - List Account | F19: closed | G19: 0020001010011800 | H19: 8180073930053234 | I19: 1 | J19: List account | K19: imps_list_account | L19: 0200 | M19: 410000 | P19: DE 39 = 52 / 53 / 39 / 42 / 14 | Q19: Declined with invalid-account code.
A20: IMPS_NA_002 | B20: Negative - Account | C20: P1 | D20: Closed Account - Outward Debit | F20: closed | G20: 0020001010011800 | H20: 8180073930053234 | I20: 1 | J20: Outward debit | K20: imps_outward | L20: 0200 | M20: 000000 | N20: 1000.00 | O20: Debit (direction tag) | P20: DE 39 = 52 / 53 / 39 / 42 / 14 | Q20: Declined with invalid-account code.
A21: IMPS_NA_003 | B21: Negative - Account | C21: P1 | D21: Closed Account - Inward Credit | F21: closed | G21: 0020001010011800 | H21: 8180073930053234 | I21: 1 | J21: Inward credit | K21: imps_inward | L21: 0200 | M21: 000000 | N21: 1000.00 | O21: Credit (direction tag) | P21: DE 39 = 52 / 53 / 39 / 42 / 14 | Q21: Credit to closed account rejected.
A22: IMPS_NA_004 | B22: Negative - Account | C22: P1 | D22: Account Not Found - Outward Debit | F22: not_found | G22: 0020009999999999 | H22: 8180073930053234 | I22: 1 | J22: Outward debit | K22: imps_outward | L22: 0200 | M22: 000000 | N22: 1000.00 | O22: Debit (direction tag) | P22: DE 39 = 52 / 53 / 39 / 42 / 14 | Q22: Declined with invalid-account code.
A23: IMPS_NA_005 | B23: Negative - Account | C23: P1 | D23: Beneficiary Not Found - Inward Credit | F23: not_found | G23: 0020009999999999 | H23: 8180073930053234 | I23: 1 | J23: Inward credit | K23: imps_inward | L23: 0200 | M23: 000000 | N23: 1000.00 | O23: Credit (direction tag) | P23: DE 39 = 52 / 53 / 39 / 42 / 14 | Q23: Declined with invalid-account code.
A24: IMPS_NA_006 | B24: Negative - Account | C24: P1 | D24: Total Freeze - Outward Debit | F24: total_freeze | G24: 0020001010011663 | H24: 8180073930053234 | I24: 1 | J24: Outward debit | K24: imps_outward | L24: 0200 | M24: 000000 | N24: 1000.00 | O24: Debit (direction tag) | P24: DE 39 = 62 / 57 / 05 | Q24: Declined 62 / 57 / 05.
A25: IMPS_NA_007 | B25: Negative - Account | C25: P1 | D25: Total Freeze - Inward Credit | F25: total_freeze | G25: 0020001010011663 | H25: 8180073930053234 | I25: 1 | J25: Inward credit | K25: imps_inward | L25: 0200 | M25: 000000 | N25: 1000.00 | O25: Credit (direction tag) | P25: DE 39 = 62 / 57 / 05 | Q25: Declined 62 / 57 / 05.
A26: IMPS_NA_008 | B26: Negative - Account | C26: P1 | D26: Debit Freeze - Outward Debit Blocked | F26: debit_freeze | G26: 0020001010011664 | H26: 8180073930053234 | I26: 1 | J26: Outward debit | K26: imps_outward | L26: 0200 | M26: 000000 | N26: 1000.00 | O26: Debit (direction tag) | P26: DE 39 = 62 / 57 / 05 | Q26: Declined 62 / 57 / 05.
A27: IMPS_NA_009 | B27: Negative - Account | C27: P1 | D27: Debit Freeze - Inward Credit Allowed | F27: debit_freeze | G27: 0020001010011664 | H27: 8180073930053234 | I27: 1 | J27: Inward credit | K27: imps_inward | L27: 0200 | M27: 000000 | N27: 100.00 | O27: Credit (direction tag) | P27: DE 39 = 00 | Q27: Credit approved 00.
I28: 2 | J28: Cleanup reversal | K28: (linked) | L28: 0420 | O28: Reversal 0420 of step 1 (DE 39 reason 68) | P28: DE 39 = 00
A29: IMPS_NA_010 | B29: Negative - Account | C29: P1 | D29: Credit Freeze - Inward Credit Blocked | F29: credit_freeze | G29: 0020001010011665 | H29: 8180073930053234 | I29: 1 | J29: Inward credit | K29: imps_inward | L29: 0200 | M29: 000000 | N29: 1000.00 | O29: Credit (direction tag) | P29: DE 39 = 62 / 57 / 05 | Q29: Declined 62 / 57 / 05.
A30: IMPS_NA_011 | B30: Negative - Account | C30: P1 | D30: Credit Freeze - Outward Debit Allowed | F30: credit_freeze | G30: 0020001010011665 | H30: 8180073930053234 | I30: 1 | J30: Outward debit | K30: imps_outward | L30: 0200 | M30: 000000 | N30: 100.00 | O30: Debit (direction tag) | P30: DE 39 = 00 | Q30: Debit approved 00.
I31: 2 | J31: Cleanup reversal | K31: (linked) | L31: 0420 | O31: Reversal 0420 of step 1 (DE 39 reason 68) | P31: DE 39 = 00
A32: IMPS_NA_012 | B32: Negative - Account | C32: P1 | D32: Dormant Account - Outward Debit | F32: dormant | G32: 0020001010011700 | H32: 8180073930053234 | I32: 1 | J32: Outward debit | K32: imps_outward | L32: 0200 | M32: 000000 | N32: 1000.00 | O32: Debit (direction tag) | P32: DE 39 = 57 / 62 / 05 | Q32: Declined 57 / 62 / 05.
A33: IMPS_NA_013 | B33: Negative - Account | C33: P1 | D33: Insufficient Funds - No Debit Posted | F33: low_funds | G33: 0020001010010999 | H33: 8180073930053234 | I33: 1 | J33: Opening balance | K33: imps_balance_enquiry | L33: 0200 | M33: 310000 | N33: 0.00 | P33: DE 39 = 00; DE present: 54 | Q33: Declined 51; balance unchanged.
I34: 2 | J34: Outward debit | K34: imps_outward | L34: 0200 | M34: 000000 | N34: 500.00 | O34: Debit (direction tag) | P34: DE 39 = 51
I35: 3 | J35: Closing balance | K35: imps_balance_enquiry | L35: 0200 | M35: 310000 | N35: 0.00 | P35: DE 39 = 00; DE present: 54; Available balance 0.00 vs step 1
A36: IMPS_BD_001 | B36: Boundary | C36: P1 | D36: Zero Amount Debit | F36: standard | G36: 0020001010000069 | H36: 8180073930053234 | I36: 1 | J36: Outward debit | K36: imps_outward | L36: 0200 | M36: 000000 | N36: 0.00 | O36: Debit (direction tag) | P36: DE 39 = 13 | Q36: Declined 13.
A37: IMPS_BD_002 | B37: Boundary | C37: P1 | D37: Debit = Per-Transaction Limit (500000.00) | F37: standard | G37: 0020001010000069 | H37: 8180073930053234 | I37: 1 | J37: Outward debit | K37: imps_outward | L37: 0200 | M37: 000000 | N37: 500000.00 | O37: Debit (direction tag) | P37: DE 39 = 00 | Q37: Approved 00 at the exact limit.
I38: 2 | J38: Cleanup reversal | K38: (linked) | L38: 0420 | O38: Reversal 0420 of step 1 (DE 39 reason 68) | P38: DE 39 = 00
A39: IMPS_BD_003 | B39: Boundary | C39: P1 | D39: Debit = Limit + 0.01 (500000.01) | F39: standard | G39: 0020001010000069 | H39: 8180073930053234 | I39: 1 | J39: Outward debit | K39: imps_outward | L39: 0200 | M39: 000000 | N39: 500000.01 | O39: Debit (direction tag) | P39: DE 39 = 61 | Q39: Declined 61.
A40: IMPS_BD_004 | B40: Boundary | C40: P2 | D40: Minimum Debit (1.00) | F40: standard | G40: 0020001010000069 | H40: 8180073930053234 | I40: 1 | J40: Outward debit | K40: imps_outward | L40: 0200 | M40: 000000 | N40: 1.00 | O40: Debit (direction tag) | P40: DE 39 = 00 | Q40: Approved 00.
...
